Workbook
Name Instalaciones: Adicionales!$S$2:$S$3
Name SegmentaciónDeDatos_Año: #N/A
Name SegmentaciónDeDatos_Cliente: #N/A
Name SegmentaciónDeDatos_Cliente1: #N/A
Name SegmentaciónDeDatos_Cpto_Llamada: #N/A
Name SegmentaciónDeDatos_Detalle_Falla: #N/A
Name SegmentaciónDeDatos_Esp_Por: #N/A
Name SegmentaciónDeDatos_Estado: #N/A
Name SegmentaciónDeDatos_Estado_Asistencia: #N/A
Name SegmentaciónDeDatos_Negocio: #N/A
Name SegmentaciónDeDatos_Red: #N/A
Name SegmentaciónDeDatos_Semana: #N/A
Name SegmentaciónDeDatos_SR: #N/A
Name SegmentaciónDeDatos_Tec_Asignado: #N/A
Name SegmentaciónDeDatos_Tec_Asignado1: #N/A
Name SegmentaciónDeDatos_Tec_Zona: #N/A
Name SegmentaciónDeDatos_Tec_Zona1: #N/A
Name SegmentaciónDeDatos_Tecnico: #N/A
Name SegmentaciónDeDatos_Zona_Local: #N/A
Name SegmentaciónDeDatos_Zona_Local1: #N/A
Name SegmentaciónDeDatos_Zona_Local2: #N/A
Name SegmentaciónDeDatos_Zona_Local3: #N/A
Name SegmentaciónDeDatos_Zona_Local4: #N/A

Sheet Agenda
A2: =Pendientes[[#Totals],[Estado Asistencia]] -> 21 | B2: =TODAY() -> 46086 | C2: 0.39583333 | D2: =B2+C2 -> 46086.396 | E2: =COUNTIF(Adicionales[Semana], WEEKNUM(TODAY())) -> 0 | M2: =_xleta.HOUR -> #VALUE! | Y2: =TODAY()-90 -> 45996 | AD2: =EXACT('Suspendidos Total'!M5531,Agenda!AC9) -> FALSE | AP2: {=COUNTIF(Despachos[Tecnico ],AL25:AL27)} -> 0 | AR2: =COUNTIF(Despachos[Tecnico ],"Deus, Mariano") -> 0 | AT2: =COUNTIFS(#REF!,"SR", Despachos[Destino],"Mar del Plata") -> #REF!
A3: Días desde última atención | B3: R | C3: % SLA | D3: T | E3: Fecha Vto | F3: Hs SLA | G3: Fecha Coor | H3: Ctrl Inicio | I3: Estado Asistencia | J3: Pedido | K3: Stock | L3: Repuestos | M3: Cliente | N3: Luno | O3: MP | P3: Direccion | Q3: Localidad | R3: Provincia | S3: Tec Asignado | T3: Desc Problema | U3: Detalle Falla | V3: Modelo | W3: Cpto Llamada | X3: Prob Encontrado | Y3: Obs Control | Z3: Esp Por | AA3: Notas Internas | AB3: Red | AC3: ID | AD3: Zona Local | AE3: Tec Zona | AP3: 0
A4: {=IFERROR(_xlfn.LET(_xlpm.dias,NETWORKDAYS(MAX(IF((Suspendidos_Total[ID]=Pendientes[[#This Row],[ID]])*(Suspendidos_Total[PEDIDO]<>Pendientes[[#This Row],[Pedido]]), Suspendidos_Total[MARCA FIN])),TODAY(),Feriados[Fecha]),_xlpm.concepto,INDEX(Suspendidos_Total[CONCEPTO LLAMADA],MATCH(MAX(IF((Suspendidos_Total[ID]=Pendientes[[#This Row],[ID]])*(Suspendidos_Total[PEDIDO]<>Pendientes[[#This Row],[Pedido]]),Suspendidos_Total[MARCA FIN])),Suspendidos_Total[MARCA FIN],0)),IF(_xlpm.dias>=20,_xlpm.concepto & CHAR(160)& "-" & CHAR(160)& INT(_xlpm.dias/20)& " " & IF(INT(_xlpm.dias/20)=1,"mes","meses") & IF(MOD(_xlpm.dias,20)>0,CHAR(160)& "," & CHAR(160)& MOD(_xlpm.dias,20)& " " & IF(MOD(_xlpm.dias,20)=1,"día","días"),""), _xlpm.concepto & CHAR(160)& "-" & CHAR(160) & IF(INT(_xlpm.dias/5)>0,INT(_xlpm.dias/5)& " " & IF(INT(_xlpm.dias/5)=1,"semana","semanas") & IF(MOD(_xlpm.dias,5)>0,CHAR(160)& "," & CHAR(160),""),"") & IF(MOD(_xlpm.dias,5)>0,MOD(_xlpm.dias,5)& " " & IF(MOD(_xlpm.dias,5)=1,"día","días"),"")) ),"")} -> SC - 4 días | B4: 2 | C4: 0.62 | E4: 46083.542 | F4: 3 | G4: 46083.417 | H4: 5,2 h | I4: SEG Asistencia | J4: 101162470 | K4: 0 | L4: - | M4: BAPRO | N4: 11369 | O4: 0 | P4: Av. Constitucion 5850 | Q4: Mar Del Plata | R4: Buenos Aires | S4: Buratti, Fabian | T4: ATM-DEPÓSITO | U4: - Falla : presenta falla en la zona de recepción del efectivo. El módulo no está operativo._x000D_ _x000D_ se agrega Falla: esta trabado el módulo de dispensador. | V4: DT-7000H34N | W4: SERVICE CALL | AB4: ATM | AC4: BAPRO 11369 | AD4: Atlántica | AE4: Buratti, Fabian | AP4: 0
A5: {=IFERROR(_xlfn.LET(_xlpm.dias,NETWORKDAYS(MAX(IF((Suspendidos_Total[ID]=Pendientes[[#This Row],[ID]])*(Suspendidos_Total[PEDIDO]<>Pendientes[[#This Row],[Pedido]]), Suspendidos_Total[MARCA FIN])),TODAY(),Feriados[Fecha]),_xlpm.concepto,INDEX(Suspendidos_Total[CONCEPTO LLAMADA],MATCH(MAX(IF((Suspendidos_Total[ID]=Pendientes[[#This Row],[ID]])*(Suspendidos_Total[PEDIDO]<>Pendientes[[#This Row],[Pedido]]),Suspendidos_Total[MARCA FIN])),Suspendidos_Total[MARCA FIN],0)),IF(_xlpm.dias>=20,_xlpm.concepto & CHAR(160)& "-" & CHAR(160)& INT(_xlpm.dias/20)& " " & IF(INT(_xlpm.dias/20)=1,"mes","meses") & IF(MOD(_xlpm.dias,20)>0,CHAR(160)& "," & CHAR(160)& MOD(_xlpm.dias,20)& " " & IF(MOD(_xlpm.dias,20)=1,"día","días"),""), _xlpm.concepto & CHAR(160)& "-" & CHAR(160) & IF(INT(_xlpm.dias/5)>0,INT(_xlpm.dias/5)& " " & IF(INT(_xlpm.dias/5)=1,"semana","semanas") & IF(MOD(_xlpm.dias,5)>0,CHAR(160)& "," & CHAR(160),""),"") & IF(MOD(_xlpm.dias,5)>0,MOD(_xlpm.dias,5)& " " & IF(MOD(_xlpm.dias,5)=1,"día","días"),"")) ),"")} -> SC - 2 semanas , 3 días | C5: 0.62 | E5: 46083.542 | F5: 5 | G5: 46083.333 | H5: 7,2 h | I5: SEG Espera | J5: 101162437 | K5: 200182777 | L5: - | M5: BAPRO | N5: 8729 | O5: 0 | P5: Av. J. Peralta Ramos 1890 | Q5: Mar Del Plata | R5: Buenos Aires | S5: SIN ASIGNAR | T5: ATM-TECLADO DE CLIENTE | U5: falla en teclado de cliente, sistema muy lento, falla en dispensa (retiene billetes), queda funcionando con fallas. | V5: DT-7000H22V | W5: SERVICE CALL | X5: Teclado cliente | Y5: [02/03/2026] se suspende por pedido de repuesto (shutter con falla en motor) | Z5: Repuesto | AB5: ATM | AC5: BAPRO 8729 | AD5: Atlántica | AE5: Buratti, Fabian
A6: {=IFERROR(_xlfn.LET(_xlpm.dias,NETWORKDAYS(MAX(IF((Suspendidos_Total[ID]=Pendientes[[#This Row],[ID]])*(Suspendidos_Total[PEDIDO]<>Pendientes[[#This Row],[Pedido]]), Suspendidos_Total[MARCA FIN])),TODAY(),Feriados[Fecha]),_xlpm.concepto,INDEX(Suspendidos_Total[CONCEPTO LLAMADA],MATCH(MAX(IF((Suspendidos_Total[ID]=Pendientes[[#This Row],[ID]])*(Suspendidos_Total[PEDIDO]<>Pendientes[[#This Row],[Pedido]]),Suspendidos_Total[MARCA FIN])),Suspendidos_Total[MARCA FIN],0)),IF(_xlpm.dias>=20,_xlpm.concepto & CHAR(160)& "-" & CHAR(160)& INT(_xlpm.dias/20)& " " & IF(INT(_xlpm.dias/20)=1,"mes","meses") & IF(MOD(_xlpm.dias,20)>0,CHAR(160)& "," & CHAR(160)& MOD(_xlpm.dias,20)& " " & IF(MOD(_xlpm.dias,20)=1,"día","días"),""), _xlpm.concepto & CHAR(160)& "-" & CHAR(160) & IF(INT(_xlpm.dias/5)>0,INT(_xlpm.dias/5)& " " & IF(INT(_xlpm.dias/5)=1,"semana","semanas") & IF(MOD(_xlpm.dias,5)>0,CHAR(160)& "," & CHAR(160),""),"") & IF(MOD(_xlpm.dias,5)>0,MOD(_xlpm.dias,5)& " " & IF(MOD(_xlpm.dias,5)=1,"día","días"),"")) ),"")} -> SC - 1 semana | B6: 1 | C6: 0.9 | E6: 46083.564 | F6: 3.0422222 | G6: 46083.438 | H6: 4,7 h | I6: SEG Asistencia | J6: 101162414 | K6: 200182749 | L6: Repuesto Enviado | M6: BAPRO | N6: 11214 | O6: 0 | P6: San Martin 1 | Q6: Pellegrini | R6: Buenos Aires | S6: Garcia, Alejandro Javier | T6: ATM-DISPENSADOR | U6: traba billetes | V6: DT-7000H34N | W6: SERVICE CALL | X6: Dispensador | Y6: [27/02/2026] Se suspende por pedido de parte (falla de motor de stacker) | Z6: Repuesto | AB6: ATM | AC6: BAPRO 11214 | AD6: Oeste | AE6: Garcia, Alejandro Javier
A7: {=IFERROR(_xlfn.LET(_xlpm.dias,NETWORKDAYS(MAX(IF((Suspendidos_Total[ID]=Pendientes[[#This Row],[ID]])*(Suspendidos_Total[PEDIDO]<>Pendientes[[#This Row],[Pedido]]), Suspendidos_Total[MARCA FIN])),TODAY(),Feriados[Fecha]),_xlpm.concepto,INDEX(Suspendidos_Total[CONCEPTO LLAMADA],MATCH(MAX(IF((Suspendidos_Total[ID]=Pendientes[[#This Row],[ID]])*(Suspendidos_Total[PEDIDO]<>Pendientes[[#This Row],[Pedido]]),Suspendidos_Total[MARCA FIN])),Suspendidos_Total[MARCA FIN],0)),IF(_xlpm.dias>=20,_xlpm.concepto & CHAR(160)& "-" & CHAR(160)& INT(_xlpm.dias/20)& " " & IF(INT(_xlpm.dias/20)=1,"mes","meses") & IF(MOD(_xlpm.dias,20)>0,CHAR(160)& "," & CHAR(160)& MOD(_xlpm.dias,20)& " " & IF(MOD(_xlpm.dias,20)=1,"día","días"),""), _xlpm.concepto & CHAR(160)& "-" & CHAR(160) & IF(INT(_xlpm.dias/5)>0,INT(_xlpm.dias/5)& " " & IF(INT(_xlpm.dias/5)=1,"semana","semanas") & IF(MOD(_xlpm.dias,5)>0,CHAR(160)& "," & CHAR(160),""),"") & IF(MOD(_xlpm.dias,5)>0,MOD(_xlpm.dias,5)& " " & IF(MOD(_xlpm.dias,5)=1,"día","días"),"")) ),"")} -> AIEC - 3 meses , 12 días | C7: 0.01 | E7: 46084.499 | F7: 25.010833 | G7: 46083.457 | H7: 4,2 h | I7: SEG Registrado | J7: 101163020 | K7: 0 | L7: - | M7: BANCO NACION | N7: 4203 | O7: 1 | P7: Rivadavia 698 | Q7: General Villegas | R7: Buenos Aires | S7: SIN ASIGNAR | T7: ATM-DISPENSADOR | U7: Dispensador con correas salidas de su posición eso genera que el ATM no dispense y quede fuera de servicio_x000D_ SLA Vence 03/03 11:42_x000D_ Prosegur 10 a 18 | V7: DT-7000H34N (FECT) | W7: SERVICE CALL | AB7: ATM | AC7: BANCO NACION 4203 | AD7: Oeste | AE7: Garcia, Alejandro Javier
A8: {=IFERROR(_xlfn.LET(_xlpm.dias,NETWORKDAYS(MAX(IF((Suspendidos_Total[ID]=Pendientes[[#This Row],[ID]])*(Suspendidos_Total[PEDIDO]<>Pendientes[[#This Row],[Pedido]]), Suspendidos_Total[MARCA FIN])),TODAY(),Feriados[Fecha]),_xlpm.concepto,INDEX(Suspendidos_Total[CONCEPTO LLAMADA],MATCH(MAX(IF((Suspendidos_Total[ID]=Pendientes[[#This Row],[ID]])*(Suspendidos_Total[PEDIDO]<>Pendientes[[#This Row],[Pedido]]),Suspendidos_Total[MARCA FIN])),Suspendidos_Total[MARCA FIN],0)),IF(_xlpm.dias>=20,_xlpm.concepto & CHAR(160)& "-" & CHAR(160)& INT(_xlpm.dias/20)& " " & IF(INT(_xlpm.dias/20)=1,"mes","meses") & IF(MOD(_xlpm.dias,20)>0,CHAR(160)& "," & CHAR(160)& MOD(_xlpm.dias,20)& " " & IF(MOD(_xlpm.dias,20)=1,"día","días"),""), _xlpm.concepto & CHAR(160)& "-" & CHAR(160) & IF(INT(_xlpm.dias/5)>0,INT(_xlpm.dias/5)& " " & IF(INT(_xlpm.dias/5)=1,"semana","semanas") & IF(MOD(_xlpm.dias,5)>0,CHAR(160)& "," & CHAR(160),""),"") & IF(MOD(_xlpm.dias,5)>0,MOD(_xlpm.dias,5)& " " & IF(MOD(_xlpm.dias,5)=1,"día","días"),"")) ),"")} -> SC - 1 semana , 3 días | C8: 0.4 | E8: 46083.761 | F8: 6.7644444 | G8: 46083.479 | H8: 3,7 h | I8: Asistencia Demorada | J8: 101162906 | K8: 0 | L8: - | M8: ACA | N8: 002359016370 | O8: 0 | P8: Diagonal F De La Palza 1733 | Q8: Miramar | R8: Buenos Aires | S8: Castaño, Matias | T8: SMC-IMPRESORA | U8: Cliente reporta que no le imprime el dispositivo, se ejecutaron las siguientes pruebas:_x000D_ Simulación de cambio de papel_x000D_ Test Print automático (fallido)_x000D_ Página de prueba de Windows (fallida)_x000D_ Configuración completa en CAOS (correcta)_x000D_ Verificación de coincidencia del nombre_x000D_ Seteo desde modo Supervisor_x000D_ _x000D_ La impresora continúa sin imprimir en ningún escenario._x000D_ Posible falla física del módulo de impresión y no un problema de configuración._x000D_ Se solicita asistencia técnica para su verificación +5492291401747 | V8: CIMA SDM500 | W8: SERVICE CALL | Y8: Cliente reporta que no le imprime el dispositivo, se ejecutaron las siguientes pruebas:_x000D_ Simulación de cambio de papel_x000D_ Test Print automático (fallido)_x000D_ Página de prueba de Windows (fallida)_x000D_ Configuración completa en CAOS (correcta)_x000D_ Verificación de coincidencia del nombre_x000D_ Seteo desde modo Supervisor_x000D_ _x000D_ La impresora continúa sin imprimir en ningún escenario._x000D_ Posible falla física del módulo de impresión y no un problema de configuración._x000D_ Se solicita asistencia técnica para su verificacion _x000D_ +5492291401747 | AB8: Cash Today | AC8: ACA 002359016370 | AD8: Atlántica | AE8: Castaño, Matias
A9: {=IFERROR(_xlfn.LET(_xlpm.dias,NETWORKDAYS(MAX(IF((Suspendidos_Total[ID]=Pendientes[[#This Row],[ID]])*(Suspendidos_Total[PEDIDO]<>Pendientes[[#This Row],[Pedido]]), Suspendidos_Total[MARCA FIN])),TODAY(),Feriados[Fecha]),_xlpm.concepto,INDEX(Suspendidos_Total[CONCEPTO LLAMADA],MATCH(MAX(IF((Suspendidos_Total[ID]=Pendientes[[#This Row],[ID]])*(Suspendidos_Total[PEDIDO]<>Pendientes[[#This Row],[Pedido]]),Suspendidos_Total[MARCA FIN])),Suspendidos_Total[MARCA FIN],0)),IF(_xlpm.dias>=20,_xlpm.concepto & CHAR(160)& "-" & CHAR(160)& INT(_xlpm.dias/20)& " " & IF(INT(_xlpm.dias/20)=1,"mes","meses") & IF(MOD(_xlpm.dias,20)>0,CHAR(160)& "," & CHAR(160)& MOD(_xlpm.dias,20)& " " & IF(MOD(_xlpm.dias,20)=1,"día","días"),""), _xlpm.concepto & CHAR(160)& "-" & CHAR(160) & IF(INT(_xlpm.dias/5)>0,INT(_xlpm.dias/5)& " " & IF(INT(_xlpm.dias/5)=1,"semana","semanas") & IF(MOD(_xlpm.dias,5)>0,CHAR(160)& "," & CHAR(160),""),"") & IF(MOD(_xlpm.dias,5)>0,MOD(_xlpm.dias,5)& " " & IF(MOD(_xlpm.dias,5)=1,"día","días"),"")) ),"")} -> MTM - 1 semana , 2 días | B9: 2 | C9: 0 | E9: 46084.466 | F9: 24.008056 | G9: 46083.466 | H9: 4,0 h | I9: SEG Registrado | J9: 101163028 | K9: 0 | L9: - | M9: BAPRO | N9: 3049 | O9: 0 | P9: Calle 2 Nº 1005 | Q9: Santa Teresita | R9: Buenos Aires | S9: SIN ASIGNAR | T9: ATM-DEPÓSITO | U9: Falla: en el módulo de depósito. Sigue presentando el mismo inconveniente que cuando vino el técnico.- | V9: DT-7000H34N | W9: SERVICE CALL | AB9: ATM | AC9: BAPRO 3049 | AD9: Atlántica | AE9: Montiel, Juan Fernando
A10: {=IFERROR(_xlfn.LET(_xlpm.dias,NETWORKDAYS(MAX(IF((Suspendidos_Total[ID]=Pendientes[[#This Row],[ID]])*(Suspendidos_Total[PEDIDO]<>Pendientes[[#This Row],[Pedido]]), Suspendidos_Total[MARCA FIN])),TODAY(),Feriados[Fecha]),_xlpm.concepto,INDEX(Suspendidos_Total[CONCEPTO LLAMADA],MATCH(MAX(IF((Suspendidos_Total[ID]=Pendientes[[#This Row],[ID]])*(Suspendidos_Total[PEDIDO]<>Pendientes[[#This Row],[Pedido]]),Suspendidos_Total[MARCA FIN])),Suspendidos_Total[MARCA FIN],0)),IF(_xlpm.dias>=20,_xlpm.concepto & CHAR(160)& "-" & CHAR(160)& INT(_xlpm.dias/20)& " " & IF(INT(_xlpm.dias/20)=1,"mes","meses") & IF(MOD(_xlpm.dias,20)>0,CHAR(160)& "," & CHAR(160)& MOD(_xlpm.dias,20)& " " & IF(MOD(_xlpm.dias,20)=1,"día","días"),""), _xlpm.concepto & CHAR(160)& "-" & CHAR(160) & IF(INT(_xlpm.dias/5)>0,INT(_xlpm.dias/5)& " " & IF(INT(_xlpm.dias/5)=1,"semana","semanas") & IF(MOD(_xlpm.dias,5)>0,CHAR(160)& "," & CHAR(160),""),"") & IF(MOD(_xlpm.dias,5)>0,MOD(_xlpm.dias,5)& " " & IF(MOD(_xlpm.dias,5)=1,"día","días"),"")) ),"")} -> SC - 1 mes , 18 días | C10: 0 | E10: 46083.747 | F10: 3.9219444 | G10: 46083.583 | H10: 1,2 h | I10: Asistencia Demorada | J10: 101162952 | K10: 0 | L10: - | M10: BAPRO | N10: 11488 | O10: 0 | P10: Avellaneda 199 | Q10: General Madariaga | R10: Buenos Aires | S10: Aldayturriaga, Martin | T10: ATM-LECTORA DE TARJETA | U10: falla en la lectora de tarjetas | V10: DT-7000H22V | W10: SERVICE CALL | AB10: ATM | AC10: BAPRO 11488 | AD10: Atlántica | AE10: Montiel, Juan Fernando
A11: {=IFERROR(_xlfn.LET(_xlpm.dias,NETWORKDAYS(MAX(IF((Suspendidos_Total[ID]=Pendientes[[#This Row],[ID]])*(Suspendidos_Total[PEDIDO]<>Pendientes[[#This Row],[Pedido]]), Suspendidos_Total[MARCA FIN])),TODAY(),Feriados[Fecha]),_xlpm.concepto,INDEX(Suspendidos_Total[CONCEPTO LLAMADA],MATCH(MAX(IF((Suspendidos_Total[ID]=Pendientes[[#This Row],[ID]])*(Suspendidos_Total[PEDIDO]<>Pendientes[[#This Row],[Pedido]]),Suspendidos_Total[MARCA FIN])),Suspendidos_Total[MARCA FIN],0)),IF(_xlpm.dias>=20,_xlpm.concepto & CHAR(160)& "-" & CHAR(160)& INT(_xlpm.dias/20)& " " & IF(INT(_xlpm.dias/20)=1,"mes","meses") & IF(MOD(_xlpm.dias,20)>0,CHAR(160)& "," & CHAR(160)& MOD(_xlpm.dias,20)& " " & IF(MOD(_xlpm.dias,20)=1,"día","días"),""), _xlpm.concepto & CHAR(160)& "-" & CHAR(160) & IF(INT(_xlpm.dias/5)>0,INT(_xlpm.dias/5)& " " & IF(INT(_xlpm.dias/5)=1,"semana","semanas") & IF(MOD(_xlpm.dias,5)>0,CHAR(160)& "," & CHAR(160),""),"") & IF(MOD(_xlpm.dias,5)>0,MOD(_xlpm.dias,5)& " " & IF(MOD(_xlpm.dias,5)=1,"día","días"),"")) ),"")} -> MTM - 1 semana , 2 días | B11: 1 | C11: 0.05 | E11: 46085.75 | F11: 56.616667 | G11: 46083.391 | H11: 5,8 h | I11: SEG Registrado | J11: 101162971 | K11: 0 | L11: - | M11: BANCO HIPOTECARIO | N11: 035TI0001 | O11: 0 | P11: General Rodriguez 726 | Q11: Tandil | R11: Buenos Aires | S11: SIN ASIGNAR | T11: ATM-DEPÓSITO | U11: Informamos que tras visita técnica el equipo continua con falla en modulo ENA | V11: TAS OPTEVA 720 R/L | W11: SERVICE CALL | AB11: ATM | AC11: BANCO HIPOTECARIO 035TI0001 | AD11: Oeste | AE11: Aldayturriaga, Martin
A12: {=IFERROR(_xlfn.LET(_xlpm.dias,NETWORKDAYS(MAX(IF((Suspendidos_Total[ID]=Pendientes[[#This Row],[ID]])*(Suspendidos_Total[PEDIDO]<>Pendientes[[#This Row],[Pedido]]), Suspendidos_Total[MARCA FIN])),TODAY(),Feriados[Fecha]),_xlpm.concepto,INDEX(Suspendidos_Total[CONCEPTO LLAMADA],MATCH(MAX(IF((Suspendidos_Total[ID]=Pendientes[[#This Row],[ID]])*(Suspendidos_Total[PEDIDO]<>Pendientes[[#This Row],[Pedido]]),Suspendidos_Total[MARCA FIN])),Suspendidos_Total[MARCA FIN],0)),IF(_xlpm.dias>=20,_xlpm.concepto & CHAR(160)& "-" & CHAR(160)& INT(_xlpm.dias/20)& " " & IF(INT(_xlpm.dias/20)=1,"mes","meses") & IF(MOD(_xlpm.dias,20)>0,CHAR(160)& "," & CHAR(160)& MOD(_xlpm.dias,20)& " " & IF(MOD(_xlpm.dias,20)=1,"día","días"),""), _xlpm.concepto & CHAR(160)& "-" & CHAR(160) & IF(INT(_xlpm.dias/5)>0,INT(_xlpm.dias/5)& " " & IF(INT(_xlpm.dias/5)=1,"semana","semanas") & IF(MOD(_xlpm.dias,5)>0,CHAR(160)& "," & CHAR(160),""),"") & IF(MOD(_xlpm.dias,5)>0,MOD(_xlpm.dias,5)& " " & IF(MOD(_xlpm.dias,5)=1,"día","días"),"")) ),"")} -> MTM - 2 semanas , 2 días | B12: 1 | C12: 0.2 | E12: 46084.42 | F12: 20.085556 | G12: 46083.583 | H12: 1,2 h | I12: Asistencia Demorada | J12: 101162995 | K12: 0 | L12: - | M12: BAPRO | N12: 6571 | O12: 0 | P12: Calle 64 3000 | Q12: Necochea | R12: Buenos Aires | S12: Chiriello, Pablo Javier | T12: ATM-IMPRESORA DE RECIBO | U12: - Falla : presenta falla en la impresión de ticket.Es un error constante que deja el atm fuera de servicio. Por el momento se encuentra funcionando , pero son arreglos temporales. | V12: DT-7000H34N | W12: SERVICE CALL | AB12: ATM | AC12: BAPRO 6571 | AD12: Atlántica | AE12: Chiriello, Pablo Javier
A13: {=IFERROR(_xlfn.LET(_xlpm.dias,NETWORKDAYS(MAX(IF((Suspendidos_Total[ID]=Pendientes[[#This Row],[ID]])*(Suspendidos_Total[PEDIDO]<>Pendientes[[#This Row],[Pedido]]), Suspendidos_Total[MARCA FIN])),TODAY(),Feriados[Fecha]),_xlpm.concepto,INDEX(Suspendidos_Total[CONCEPTO LLAMADA],MATCH(MAX(IF((Suspendidos_Total[ID]=Pendientes[[#This Row],[ID]])*(Suspendidos_Total[PEDIDO]<>Pendientes[[#This Row],[Pedido]]),Suspendidos_Total[MARCA FIN])),Suspendidos_Total[MARCA FIN],0)),IF(_xlpm.dias>=20,_xlpm.concepto & CHAR(160)& "-" & CHAR(160)& INT(_xlpm.dias/20)& " " & IF(INT(_xlpm.dias/20)=1,"mes","meses") & IF(MOD(_xlpm.dias,20)>0,CHAR(160)& "," & CHAR(160)& MOD(_xlpm.dias,20)& " " & IF(MOD(_xlpm.dias,20)=1,"día","días"),""), _xlpm.concepto & CHAR(160)& "-" & CHAR(160) & IF(INT(_xlpm.dias/5)>0,INT(_xlpm.dias/5)& " " & IF(INT(_xlpm.dias/5)=1,"semana","semanas") & IF(MOD(_xlpm.dias,5)>0,CHAR(160)& "," & CHAR(160),""),"") & IF(MOD(_xlpm.dias,5)>0,MOD(_xlpm.dias,5)& " " & IF(MOD(_xlpm.dias,5)=1,"día","días"),"")) ),"")} -> MTM - 1 semana , 2 días | B13: 2 | C13: 0.62 | E13: 46083.542 | F13: 5 | G13: 46083.333 | H13: 7,2 h | I13: SEG Asistencia | J13: 101162436 | K13: 200182779 | L13: - | M13: BAPRO | N13: 8728 | O13: 0 | P13: Av. J. Peralta Ramos 1890 | Q13: Mar Del Plata | R13: Buenos Aires | S13: Chiriello, Pablo Javier | T13: ATM-LECTORA DE TARJETA | U13: Falla: falla en lectora de tarjetas, queda en servicio con falla. | V13: DT-7000H22V | W13: SERVICE CALL | AB13: ATM | AC13: BAPRO 8728 | AD13: Atlántica | AE13: Chiriello, Pablo Javier
A14: {=IFERROR(_xlfn.LET(_xlpm.dias,NETWORKDAYS(MAX(IF((Suspendidos_Total[ID]=Pendientes[[#This Row],[ID]])*(Suspendidos_Total[PEDIDO]<>Pendientes[[#This Row],[Pedido]]), Suspendidos_Total[MARCA FIN])),TODAY(),Feriados[Fecha]),_xlpm.concepto,INDEX(Suspendidos_Total[CONCEPTO LLAMADA],MATCH(MAX(IF((Suspendidos_Total[ID]=Pendientes[[#This Row],[ID]])*(Suspendidos_Total[PEDIDO]<>Pendientes[[#This Row],[Pedido]]),Suspendidos_Total[MARCA FIN])),Suspendidos_Total[MARCA FIN],0)),IF(_xlpm.dias>=20,_xlpm.concepto & CHAR(160)& "-" & CHAR(160)& INT(_xlpm.dias/20)& " " & IF(INT(_xlpm.dias/20)=1,"mes","meses") & IF(MOD(_xlpm.dias,20)>0,CHAR(160)& "," & CHAR(160)& MOD(_xlpm.dias,20)& " " & IF(MOD(_xlpm.dias,20)=1,"día","días"),""), _xlpm.concepto & CHAR(160)& "-" & CHAR(160) & IF(INT(_xlpm.dias/5)>0,INT(_xlpm.dias/5)& " " & IF(INT(_xlpm.dias/5)=1,"semana","semanas") & IF(MOD(_xlpm.dias,5)>0,CHAR(160)& "," & CHAR(160),""),"") & IF(MOD(_xlpm.dias,5)>0,MOD(_xlpm.dias,5)& " " & IF(MOD(_xlpm.dias,5)=1,"día","días"),"")) ),"")} -> SC - 2 semanas | B14: 3 | C14: 0.12 | E14: 46084.583 | F14: 25 | G14: 46083.542 | H14: 2,2 h | I14: Asistencia Demorada | J14: 101162508 | K14: 200182770 | L14: - | M14: BANCO CREDICOOP | N14: 812051 | O14: 0 | P14: Sarmiento 2200 | Q14: Bahia Blanca | R14: Buenos Aires | S14: Pavon, Diego Emanuel | T14: ATM-ACEPTADOR DE BILLETES | U14: Falla en Depósitos de Acreditación Inmediata:_x000D_ El ATM no muestra errores pero rechaza casi todos los billetes, tomando apenas 2 o 3 billetes por transacción de depósito. | V14: ATM FULL OPTEVA 720 R/L ENA/ 5 GAV EDC R | W14: SERVICE CALL | AB14: ATM | AC14: BANCO CREDICOOP 812051 | AD14: Centro | AE14: Pavon, Diego Emanuel
A15: {=IFERROR(_xlfn.LET(_xlpm.dias,NETWORKDAYS(MAX(IF((Suspendidos_Total[ID]=Pendientes[[#This Row],[ID]])*(Suspendidos_Total[PEDIDO]<>Pendientes[[#This Row],[Pedido]]), Suspendidos_Total[MARCA FIN])),TODAY(),Feriados[Fecha]),_xlpm.concepto,INDEX(Suspendidos_Total[CONCEPTO LLAMADA],MATCH(MAX(IF((Suspendidos_Total[ID]=Pendientes[[#This Row],[ID]])*(Suspendidos_Total[PEDIDO]<>Pendientes[[#This Row],[Pedido]]),Suspendidos_Total[MARCA FIN])),Suspendidos_Total[MARCA FIN],0)),IF(_xlpm.dias>=20,_xlpm.concepto & CHAR(160)& "-" & CHAR(160)& INT(_xlpm.dias/20)& " " & IF(INT(_xlpm.dias/20)=1,"mes","meses") & IF(MOD(_xlpm.dias,20)>0,CHAR(160)& "," & CHAR(160)& MOD(_xlpm.dias,20)& " " & IF(MOD(_xlpm.dias,20)=1,"día","días"),""), _xlpm.concepto & CHAR(160)& "-" & CHAR(160) & IF(INT(_xlpm.dias/5)>0,INT(_xlpm.dias/5)& " " & IF(INT(_xlpm.dias/5)=1,"semana","semanas") & IF(MOD(_xlpm.dias,5)>0,CHAR(160)& "," & CHAR(160),""),"") & IF(MOD(_xlpm.dias,5)>0,MOD(_xlpm.dias,5)& " " & IF(MOD(_xlpm.dias,5)=1,"día","días"),"")) ),"")} -> SC - 1 mes | B15: 2 | C15: 0.34 | E15: 46084.5 | F15: 26.993611 | G15: 46083.375 | H15: 6,2 h | I15: SEG Asistencia | J15: 101162427 | K15: 0 | L15: - | M15: BANCO CREDICOOP | N15: 812961 | O15: 0 | P15: Garibaldi 360 | Q15: Bahia Blanca | R15: Buenos Aires | S15: Pavon, Diego Emanuel | T15: ATM-DISPENSADOR | U15: Descripción: Fallas aleatorias de dispensador. Revisión de módulo y gavetas. | V15: ATM FULL OPTEVA 720 R/L ENA | W15: SERVICE CALL | AB15: ATM | AC15: BANCO CREDICOOP 812961 | AD15: Centro | AE15: Pavon, Diego Emanuel
A16: {=IFERROR(_xlfn.LET(_xlpm.dias,NETWORKDAYS(MAX(IF((Suspendidos_Total[ID]=Pendientes[[#This Row],[ID]])*(Suspendidos_Total[PEDIDO]<>Pendientes[[#This Row],[Pedido]]), Suspendidos_Total[MARCA FIN])),TODAY(),Feriados[Fecha]),_xlpm.concepto,INDEX(Suspendidos_Total[CONCEPTO LLAMADA],MATCH(MAX(IF((Suspendidos_Total[ID]=Pendientes[[#This Row],[ID]])*(Suspendidos_Total[PEDIDO]<>Pendientes[[#This Row],[Pedido]]),Suspendidos_Total[MARCA FIN])),Suspendidos_Total[MARCA FIN],0)),IF(_xlpm.dias>=20,_xlpm.concepto & CHAR(160)& "-" & CHAR(160)& INT(_xlpm.dias/20)& " " & IF(INT(_xlpm.dias/20)=1,"mes","meses") & IF(MOD(_xlpm.dias,20)>0,CHAR(160)& "," & CHAR(160)& MOD(_xlpm.dias,20)& " " & IF(MOD(_xlpm.dias,20)=1,"día","días"),""), _xlpm.concepto & CHAR(160)& "-" & CHAR(160) & IF(INT(_xlpm.dias/5)>0,INT(_xlpm.dias/5)& " " & IF(INT(_xlpm.dias/5)=1,"semana","semanas") & IF(MOD(_xlpm.dias,5)>0,CHAR(160)& "," & CHAR(160),""),"") & IF(MOD(_xlpm.dias,5)>0,MOD(_xlpm.dias,5)& " " & IF(MOD(_xlpm.dias,5)=1,"día","días"),"")) ),"")} -> SC - 5 meses , 10 días | C16: 0.35 | E16: 46084.498 | F16: 26.961111 | G16: 46083.375 | H16: 6,2 h | I16: SEG Asistencia | J16: 101162426 | K16: 0 | L16: - | M16: BANCO CREDICOOP | N16: 812951 | O16: 1 | P16: Garibaldi 360 | Q16: Bahia Blanca | R16: Buenos Aires | S16: Pavon, Diego Emanuel | T16: ATM-DISPENSADOR | U16: Descripción: Fallas aleatorias de dispensador. Revisión de módulo y gavetas. | V16: ATM FULL OPTEVA 720 R/L 5ºGAV | W16: SERVICE CALL | AB16: ATM | AC16: BANCO CREDICOOP 812951 | AD16: Centro | AE16: Pavon, Diego Emanuel
A17: {=IFERROR(_xlfn.LET(_xlpm.dias,NETWORKDAYS(MAX(IF((Suspendidos_Total[ID]=Pendientes[[#This Row],[ID]])*(Suspendidos_Total[PEDIDO]<>Pendientes[[#This Row],[Pedido]]), Suspendidos_Total[MARCA FIN])),TODAY(),Feriados[Fecha]),_xlpm.concepto,INDEX(Suspendidos_Total[CONCEPTO LLAMADA],MATCH(MAX(IF((Suspendidos_Total[ID]=Pendientes[[#This Row],[ID]])*(Suspendidos_Total[PEDIDO]<>Pendientes[[#This Row],[Pedido]]),Suspendidos_Total[MARCA FIN])),Suspendidos_Total[MARCA FIN],0)),IF(_xlpm.dias>=20,_xlpm.concepto & CHAR(160)& "-" & CHAR(160)& INT(_xlpm.dias/20)& " " & IF(INT(_xlpm.dias/20)=1,"mes","meses") & IF(MOD(_xlpm.dias,20)>0,CHAR(160)& "," & CHAR(160)& MOD(_xlpm.dias,20)& " " & IF(MOD(_xlpm.dias,20)=1,"día","días"),""), _xlpm.concepto & CHAR(160)& "-" & CHAR(160) & IF(INT(_xlpm.dias/5)>0,INT(_xlpm.dias/5)& " " & IF(INT(_xlpm.dias/5)=1,"semana","semanas") & IF(MOD(_xlpm.dias,5)>0,CHAR(160)& "," & CHAR(160),""),"") & IF(MOD(_xlpm.dias,5)>0,MOD(_xlpm.dias,5)& " " & IF(MOD(_xlpm.dias,5)=1,"día","días"),"")) ),"")} -> SC - 7 meses , 12 días | C17: 0.35 | E17: 46084.498 | F17: 26.951944 | G17: 46083.375 | H17: 6,2 h | I17: SEG Asistencia | J17: 101162424 | K17: 0 | L17: - | M17: BANCO CREDICOOP | N17: 812931 | O17: 1 | P17: Garibaldi 360 | Q17: Bahia Blanca | R17: Buenos Aires | S17: Pavon, Diego Emanuel | T17: ATM-DISPENSADOR | U17: Descripción: Fallas aleatorias de dispensador. Revisión de módulo y gavetas. | V17: ATM FULL OPTEVA 720 R/L | W17: SERVICE CALL | AB17: ATM | AC17: BANCO CREDICOOP 812931 | AD17: Centro | AE17: Pavon, Diego Emanuel
A18: {=IFERROR(_xlfn.LET(_xlpm.dias,NETWORKDAYS(MAX(IF((Suspendidos_Total[ID]=Pendientes[[#This Row],[ID]])*(Suspendidos_Total[PEDIDO]<>Pendientes[[#This Row],[Pedido]]), Suspendidos_Total[MARCA FIN])),TODAY(),Feriados[Fecha]),_xlpm.concepto,INDEX(Suspendidos_Total[CONCEPTO LLAMADA],MATCH(MAX(IF((Suspendidos_Total[ID]=Pendientes[[#This Row],[ID]])*(Suspendidos_Total[PEDIDO]<>Pendientes[[#This Row],[Pedido]]),Suspendidos_Total[MARCA FIN])),Suspendidos_Total[MARCA FIN],0)),IF(_xlpm.dias>=20,_xlpm.concepto & CHAR(160)& "-" & CHAR(160)& INT(_xlpm.dias/20)& " " & IF(INT(_xlpm.dias/20)=1,"mes","meses") & IF(MOD(_xlpm.dias,20)>0,CHAR(160)& "," & CHAR(160)& MOD(_xlpm.dias,20)& " " & IF(MOD(_xlpm.dias,20)=1,"día","días"),""), _xlpm.concepto & CHAR(160)& "-" & CHAR(160) & IF(INT(_xlpm.dias/5)>0,INT(_xlpm.dias/5)& " " & IF(INT(_xlpm.dias/5)=1,"semana","semanas") & IF(MOD(_xlpm.dias,5)>0,CHAR(160)& "," & CHAR(160),""),"") & IF(MOD(_xlpm.dias,5)>0,MOD(_xlpm.dias,5)& " " & IF(MOD(_xlpm.dias,5)=1,"día","días"),"")) ),"")} -> MTM - 5 meses , 1 día | C18: 0 | E18: 46085.424 | F18: 45.676111 | G18: 46083.521 | H18: 2,7 h | I18: Asistencia Demorada | J18: 101163027 | K18: 0 | L18: - | M18: BANCO CREDICOOP | N18: 823031 | O18: 1 | P18: Vicente Lopez 3045 | Q18: Olavarria | R18: Buenos Aires | S18: Martos, Jose Angel | T18: ATM-DEPÓSITO | U18: Descripción: hace la apertura del buzón pero no toma el efectivo y hace ruido en los engranajes | V18: ATM FULL OPTEVA 720 R/L ENA/ 5 GAV | W18: SERVICE CALL | AB18: ATM | AC18: BANCO CREDICOOP 823031 | AD18: Oeste | AE18: Martos, Jose Angel
A19: {=IFERROR(_xlfn.LET(_xlpm.dias,NETWORKDAYS(MAX(IF((Suspendidos_Total[ID]=Pendientes[[#This Row],[ID]])*(Suspendidos_Total[PEDIDO]<>Pendientes[[#This Row],[Pedido]]), Suspendidos_Total[MARCA FIN])),TODAY(),Feriados[Fecha]),_xlpm.concepto,INDEX(Suspendidos_Total[CONCEPTO LLAMADA],MATCH(MAX(IF((Suspendidos_Total[ID]=Pendientes[[#This Row],[ID]])*(Suspendidos_Total[PEDIDO]<>Pendientes[[#This Row],[Pedido]]),Suspendidos_Total[MARCA FIN])),Suspendidos_Total[MARCA FIN],0)),IF(_xlpm.dias>=20,_xlpm.concepto & CHAR(160)& "-" & CHAR(160)& INT(_xlpm.dias/20)& " " & IF(INT(_xlpm.dias/20)=1,"mes","meses") & IF(MOD(_xlpm.dias,20)>0,CHAR(160)& "," & CHAR(160)& MOD(_xlpm.dias,20)& " " & IF(MOD(_xlpm.dias,20)=1,"día","días"),""), _xlpm.concepto & CHAR(160)& "-" & CHAR(160) & IF(INT(_xlpm.dias/5)>0,INT(_xlpm.dias/5)& " " & IF(INT(_xlpm.dias/5)=1,"semana","semanas") & IF(MOD(_xlpm.dias,5)>0,CHAR(160)& "," & CHAR(160),""),"") & IF(MOD(_xlpm.dias,5)>0,MOD(_xlpm.dias,5)& " " & IF(MOD(_xlpm.dias,5)=1,"día","días"),"")) ),"")} -> MTM - 1 semana , 1 día | B19: 5 | C19: 0.95 | E19: 46083.482 | F19: -1.4305556 | G19: 46083.542 | H19: 2,2 h | I19: Asistencia Demorada | J19: 101162157 | K19: 200182737 | L19: Repuesto Enviado | M19: BANCO CREDICOOP | N19: 814621 | O19: 0 | P19: 9 de Julio 270 | Q19: Trelew | R19: Chubut | S19: Godoy, Diego | T19: ATM-DISPENSADOR | U19: REITERA FALLA EN DISPENSADOR | V19: DT-7000H22V | W19: SERVICE CALL | X19: Dispensador | Y19: [27/02/2026] Se suspende por pedido de repuesto. Por recomendación de sector Especialista se solicita Shutter. | Z19: Repuesto | AA19: Se realizaron pruebas en dispensador con soporte de Especialista Walter Formaggio. Se reviso sensor y resorte de presenter. se realizaron pruebas de apertura y cierre en Shutter. Pruebas OK. se extrajeron LOGS de errores. Se realizaron pruebas de extracción ($14.0000, $25.000 y $40.000) con funcionario bancario. Pruebas OK. el equipo quedó operativo y en servicio. | AB19: ATM | AC19: BANCO CREDICOOP 814621 | AD19: Sur | AE19: Godoy, Diego
A20: {=IFERROR(_xlfn.LET(_xlpm.dias,NETWORKDAYS(MAX(IF((Suspendidos_Total[ID]=Pendientes[[#This Row],[ID]])*(Suspendidos_Total[PEDIDO]<>Pendientes[[#This Row],[Pedido]]), Suspendidos_Total[MARCA FIN])),TODAY(),Feriados[Fecha]),_xlpm.concepto,INDEX(Suspendidos_Total[CONCEPTO LLAMADA],MATCH(MAX(IF((Suspendidos_Total[ID]=Pendientes[[#This Row],[ID]])*(Suspendidos_Total[PEDIDO]<>Pendientes[[#This Row],[Pedido]]),Suspendidos_Total[MARCA FIN])),Suspendidos_Total[MARCA FIN],0)),IF(_xlpm.dias>=20,_xlpm.concepto & CHAR(160)& "-" & CHAR(160)& INT(_xlpm.dias/20)& " " & IF(INT(_xlpm.dias/20)=1,"mes","meses") & IF(MOD(_xlpm.dias,20)>0,CHAR(160)& "," & CHAR(160)& MOD(_xlpm.dias,20)& " " & IF(MOD(_xlpm.dias,20)=1,"día","días"),""), _xlpm.concepto & CHAR(160)& "-" & CHAR(160) & IF(INT(_xlpm.dias/5)>0,INT(_xlpm.dias/5)& " " & IF(INT(_xlpm.dias/5)=1,"semana","semanas") & IF(MOD(_xlpm.dias,5)>0,CHAR(160)& "," & CHAR(160),""),"") & IF(MOD(_xlpm.dias,5)>0,MOD(_xlpm.dias,5)& " " & IF(MOD(_xlpm.dias,5)=1,"día","días"),"")) ),"")} -> SC - 2 semanas , 4 días | B20: 2 | C20: 1 | E20: 46080.621 | F20: -67.088889 | G20: 46083.417 | H20: 5,2 h | I20: SEG Asistencia | J20: 101162329 | K20: 200182755 | L20: Repuesto Enviado | M20: BANCO NACION | N20: 5060 | O20: 0 | P20: 9 de Julio 127 | Q20: Puerto Madryn | R20: Chubut | S20: Godoy, Diego | T20: ATM-MONITOR DE CLIENTE | U20: Pantalla de clientes y teclado no funcionan_x000D_ SLA Vence 27/02 14:52_x000D_ Prosegur 08 a 16 | V20: ATM OPTEVA 522 | W20: SERVICE CALL | X20: Monitor cliente | Y20: [27/02/2026] Tecla de función en monitor en mal estado y trabada. Se realizan pruebas. Falla persiste. Se suspende por repuesto | Z20: Repuesto | AB20: ATM | AC20: BANCO NACION 5060 | AD20: Sur | AE20: Godoy, Diego
A21: {=IFERROR(_xlfn.LET(_xlpm.dias,NETWORKDAYS(MAX(IF((Suspendidos_Total[ID]=Pendientes[[#This Row],[ID]])*(Suspendidos_Total[PEDIDO]<>Pendientes[[#This Row],[Pedido]]), Suspendidos_Total[MARCA FIN])),TODAY(),Feriados[Fecha]),_xlpm.concepto,INDEX(Suspendidos_Total[CONCEPTO LLAMADA],MATCH(MAX(IF((Suspendidos_Total[ID]=Pendientes[[#This Row],[ID]])*(Suspendidos_Total[PEDIDO]<>Pendientes[[#This Row],[Pedido]]),Suspendidos_Total[MARCA FIN])),Suspendidos_Total[MARCA FIN],0)),IF(_xlpm.dias>=20,_xlpm.concepto & CHAR(160)& "-" & CHAR(160)& INT(_xlpm.dias/20)& " " & IF(INT(_xlpm.dias/20)=1,"mes","meses") & IF(MOD(_xlpm.dias,20)>0,CHAR(160)& "," & CHAR(160)& MOD(_xlpm.dias,20)& " " & IF(MOD(_xlpm.dias,20)=1,"día","días"),""), _xlpm.concepto & CHAR(160)& "-" & CHAR(160) & IF(INT(_xlpm.dias/5)>0,INT(_xlpm.dias/5)& " " & IF(INT(_xlpm.dias/5)=1,"semana","semanas") & IF(MOD(_xlpm.dias,5)>0,CHAR(160)& "," & CHAR(160),""),"") & IF(MOD(_xlpm.dias,5)>0,MOD(_xlpm.dias,5)& " " & IF(MOD(_xlpm.dias,5)=1,"día","días"),"")) ),"")} -> SC - 1 mes , 18 días | C21: 0.51 | E21: 46083.705 | F21: 4.9227778 | G21: 46083.5 | H21: 3,2 h | I21: Asistencia Demorada | J21: 101162889 | K21: 0 | L21: - | M21: CENCOSUD S.A | N21: 008681061970 | O21: 0 | P21: Manuel Belgrano 372 | Q21: Puerto Madryn | R21: Chubut | S21: Godoy, Diego | T21: SMC-CPU | U21: cte reclama que la PC no inicia, aparece error en disco. se solicita asistencia | V21: GLORY P500 | W21: SERVICE CALL | Y21: cte reclama que la PC no inicia, aparece error en disco. se solicita asistencia_x000D_ Horarios: de 8.30 a 21 hs_x000D_ Contacto:2804205750 Carla | AB21: Cash Today | AC21: CENCOSUD S.A 008681061970 | AD21: Sur | AE21: Godoy, Diego
A22: {=IFERROR(_xlfn.LET(_xlpm.dias,NETWORKDAYS(MAX(IF((Suspendidos_Total[ID]=Pendientes[[#This Row],[ID]])*(Suspendidos_Total[PEDIDO]<>Pendientes[[#This Row],[Pedido]]), Suspendidos_Total[MARCA FIN])),TODAY(),Feriados[Fecha]),_xlpm.concepto,INDEX(Suspendidos_Total[CONCEPTO LLAMADA],MATCH(MAX(IF((Suspendidos_Total[ID]=Pendientes[[#This Row],[ID]])*(Suspendidos_Total[PEDIDO]<>Pendientes[[#This Row],[Pedido]]),Suspendidos_Total[MARCA FIN])),Suspendidos_Total[MARCA FIN],0)),IF(_xlpm.dias>=20,_xlpm.concepto & CHAR(160)& "-" & CHAR(160)& INT(_xlpm.dias/20)& " " & IF(INT(_xlpm.dias/20)=1,"mes","meses") & IF(MOD(_xlpm.dias,20)>0,CHAR(160)& "," & CHAR(160)& MOD(_xlpm.dias,20)& " " & IF(MOD(_xlpm.dias,20)=1,"día","días"),""), _xlpm.concepto & CHAR(160)& "-" & CHAR(160) & IF(INT(_xlpm.dias/5)>0,INT(_xlpm.dias/5)& " " & IF(INT(_xlpm.dias/5)=1,"semana","semanas") & IF(MOD(_xlpm.dias,5)>0,CHAR(160)& "," & CHAR(160),""),"") & IF(MOD(_xlpm.dias,5)>0,MOD(_xlpm.dias,5)& " " & IF(MOD(_xlpm.dias,5)=1,"día","días"),"")) ),"")} -> MTM - 4 meses , 3 días | C22: 0.13 | E22: 46084.456 | F22: 25.006944 | G22: 46083.414 | H22: 5,3 h | I22: SEG Registrado | J22: 101162985 | K22: 0 | L22: - | M22: BANCO NACION | N22: 5031 | O22: 0 | P22: Av. San Martin 2598 | Q22: El Bolson | R22: Rio Negro | S22: SIN ASIGNAR | T22: ATM-DISPENSADOR | U22: Modulo 1 con error. No ingresa carro con gavetas, no traba y no entra en servicio. Lector de huella caido y eso imposibilita que el carro con gavetas trabe y pueda dispensar dinero_x000D_ _x000D_ SLA Vence 03/03 10:50hs_x000D_ TELLEX 8 a 16hs | V22: ATM OPTEVA 522 | W22: SERVICE CALL | AB22: ATM | AC22: BANCO NACION 5031 | AD22: Suroeste | AE22: Ibañez, Pablo Fernando
A23: {=IFERROR(_xlfn.LET(_xlpm.dias,NETWORKDAYS(MAX(IF((Suspendidos_Total[ID]=Pendientes[[#This Row],[ID]])*(Suspendidos_Total[PEDIDO]<>Pendientes[[#This Row],[Pedido]]), Suspendidos_Total[MARCA FIN])),TODAY(),Feriados[Fecha]),_xlpm.concepto,INDEX(Suspendidos_Total[CONCEPTO LLAMADA],MATCH(MAX(IF((Suspendidos_Total[ID]=Pendientes[[#This Row],[ID]])*(Suspendidos_Total[PEDIDO]<>Pendientes[[#This Row],[Pedido]]),Suspendidos_Total[MARCA FIN])),Suspendidos_Total[MARCA FIN],0)),IF(_xlpm.dias>=20,_xlpm.concepto & CHAR(160)& "-" & CHAR(160)& INT(_xlpm.dias/20)& " " & IF(INT(_xlpm.dias/20)=1,"mes","meses") & IF(MOD(_xlpm.dias,20)>0,CHAR(160)& "," & CHAR(160)& MOD(_xlpm.dias,20)& " " & IF(MOD(_xlpm.dias,20)=1,"día","días"),""), _xlpm.concepto & CHAR(160)& "-" & CHAR(160) & IF(INT(_xlpm.dias/5)>0,INT(_xlpm.dias/5)& " " & IF(INT(_xlpm.dias/5)=1,"semana","semanas") & IF(MOD(_xlpm.dias,5)>0,CHAR(160)& "," & CHAR(160),""),"") & IF(MOD(_xlpm.dias,5)>0,MOD(_xlpm.dias,5)& " " & IF(MOD(_xlpm.dias,5)=1,"día","días"),"")) ),"")} -> SC - 4 días | C23: 0.14 | E23: 46083.893 | F23: 11.92 | G23: 46083.396 | H23: 5,7 h | I23: SEG Asistencia | J23: 101162732 | K23: 0 | L23: - | M23: CARREFOUR | N23: 006624021970 | O23: 0 | P23: Av. Olascoaga 350 | Q23: Neuquen | R23: Neuquen | S23: Ibañez, Pablo Fernando | T23: SMC-ERROR RECONTADORA | U23: El cliente se comunica por la misma falla anterior, no lee billetes de mil de San Martin. | V23: GLORY P500 | W23: SERVICE CALL | Y23: a confirmar ope ///Se pide asistencia tecnica para chequear el tema de lectura de los billetes de mil de San Martin, favor de hacer varias pruebas ya que el error persiste. Horario de 8 a 22. | Z23: Cliente | AB23: Cash Today | AC23: CARREFOUR 006624021970 | AD23: Suroeste | AE23: Ibañez, Pablo Fernando
A24: {=IFERROR(_xlfn.LET(_xlpm.dias,NETWORKDAYS(MAX(IF((Suspendidos_Total[ID]=Pendientes[[#This Row],[ID]])*(Suspendidos_Total[PEDIDO]<>Pendientes[[#This Row],[Pedido]]), Suspendidos_Total[MARCA FIN])),TODAY(),Feriados[Fecha]),_xlpm.concepto,INDEX(Suspendidos_Total[CONCEPTO LLAMADA],MATCH(MAX(IF((Suspendidos_Total[ID]=Pendientes[[#This Row],[ID]])*(Suspendidos_Total[PEDIDO]<>Pendientes[[#This Row],[Pedido]]),Suspendidos_Total[MARCA FIN])),Suspendidos_Total[MARCA FIN],0)),IF(_xlpm.dias>=20,_xlpm.concepto & CHAR(160)& "-" & CHAR(160)& INT(_xlpm.dias/20)& " " & IF(INT(_xlpm.dias/20)=1,"mes","meses") & IF(MOD(_xlpm.dias,20)>0,CHAR(160)& "," & CHAR(160)& MOD(_xlpm.dias,20)& " " & IF(MOD(_xlpm.dias,20)=1,"día","días"),""), _xlpm.concepto & CHAR(160)& "-" & CHAR(160) & IF(INT(_xlpm.dias/5)>0,INT(_xlpm.dias/5)& " " & IF(INT(_xlpm.dias/5)=1,"semana","semanas") & IF(MOD(_xlpm.dias,5)>0,CHAR(160)& "," & CHAR(160),""),"") & IF(MOD(_xlpm.dias,5)>0,MOD(_xlpm.dias,5)& " " & IF(MOD(_xlpm.dias,5)=1,"día","días"),"")) ),"")} -> AIEC - 3 meses , 12 días | C24: 1 | E24: 46080.875 | F24: -73.366667 | G24: 46083.932 | I24: SEG Espera Llegada | J24: 101162319 | K24: 0 | L24: - | M24: SAIEP | N24: 004677006870 | O24: 0 | P24: Av. Ángel Gallardo 801 | Q24: San Carlos De Bariloche | R24: Rio Negro | S24: SIN ASIGNAR | T24: SMC-FALLA EN TRANSPORTE | U24: en ocasiones queda algún billete que no es tomado en el deposito de un cajero pero tampoco indica error ni informa billete trabado y luego es considerado en el deposito siguiente ( estimamos que queda en algún lado intermedio entre donde se puede observar por nosotros y antes de pasar por el sensor y bolsa de deposito) | V24: CIMA SDM500 | W24: SERVICE CALL | Y24: en ocasiones queda algún billete que no es tomado en el deposito de un cajero pero tampoco indica error ni informa billete trabado y luego es considerado en el deposito siguiente ( estimamos que queda en algún lado intermedio entre donde se puede observar por nosotros y antes de pasar por el sensor y bolsa de deposito) | AB24: Cash Today | AC24: SAIEP 004677006870 | AD24: Suroeste | AE24: Ibañez, Pablo Fernando
C25: Total | I25: =SUBTOTAL(103,Pendientes[Estado Asistencia]) -> 21 | AB25: =SUBTOTAL(103,Pendientes[Red]) -> 21

Sheet Zonas
B1: Técnico | C1: B | D1: c
B2: Aldayturriaga, Martin | C2: 3 | D2: 1
B3: Allende, Martin Leandro | C3: 4 | D3: 1 | E3: Mail a Rossi reclamando
B4: Buratti, Fabian | C4: 1
B5: Castaño, Matias | C5: 20 | D5: 1
B6: Christiansen, Patricio | C6: 4
B7: Corti Victor | C7: 3
B8: Foschi, Alejandro | C8: 14 | D8: 1
B9: Garcia, Alejandro Javier | C9: 2 | D9: 1
B10: Godoy, Diego | C10: 11 | D10: 1
B11: Gonzalez Cabrera, Antonio | C11: 5 | D11: 1
B12: Hernandez, Marcos Alberto | C12: 2 | D12: 1
B13: Lemos, Daniel | C13: 5
B14: Liscio, Leonardo Gastón | C14: 6 | D14: 1
B15: Martos, Jose Angel | C15: 2 | D15: 1
B16: Miranda, Matias | C16: 9
B17: Osorio, Gabriel | C17: 4
B18: Vicente, Francisco Ariel | C18: 3 | D18: 1
A21: Zona Local | B21: TECNICO | C21: Zona | E21: Zona Local | F21: TECNICO | G21: Zona
A22: Atlántica | B22: Buratti, Fabian | C22: IN MDP 2 | E22: Atlántica | F22: Buratti, Fabian | G22: IN MDP 2
A23: Atlántica | B23: Castaño, Matias | C23: IN MDP3 | E23: Atlántica | F23: Castaño, Matias | G23: IN MDP3 | K23: García | L23: 7
A24: Atlántica | B24: Montiel, Juan Fernando | C24: IN COS | E24: Atlántica | F24: Montiel, Juan Fernando | G24: IN COS | K24: Mateo | L24: 4
A25: Atlántica | B25: Chiriello, Pablo Javier | C25: IN MDP 1 | E25: Atlántica | F25: Chiriello, Pablo Javier | G25: IN MDP 1 | K25: Godoy | L25: 7
A26: Centro | B26: Christiansen, Patricio | C26: IN BB1 | E26: Centro | F26: Christiansen, Patricio | G26: IN BB1 | I26: {=_xlfn.UNIQUE(DetalleZonasTécnicas[Zona Local])} -> Atlántica
A27: Centro | B27: Pavon, Diego Emanuel | C27: IN BB2 | E27: Centro | F27: Pavon, Diego Emanuel | G27: IN BB2 | I27: Centro
A28: Centro | B28: Rodriguez, Mateo Joaquin | C28: IN CSZ | E28: Centro | F28: Rodriguez, Mateo Joaquin | G28: IN CSZ | I28: Contratistas
A29: Centro | B29: Vicente, Francisco Ariel | C29: IN VIE | E29: Centro | F29: Vicente, Francisco Ariel | G29: IN VIE | I29: La Pampa
A30: Contratistas | B30: Barrera, Fernando Andrés | C30: IN RIT | E30: Contratistas | F30: Barrera, Fernando Andrés | G30: IN RIT | I30: Oeste
A31: Contratistas | B31: Corti Victor | C31: IN RGR | E31: Contratistas | F31: Corti Victor | G31: IN RGR | I31: Sur
A32: Contratistas | B32: Foschi, Alejandro | C32: IN RGA | E32: Contratistas | F32: Foschi, Alejandro | G32: IN RGA | I32: Suroeste
A33: Contratistas | B33: Lemos, Daniel | C33: IN USH | E33: Contratistas | F33: Lemos, Daniel | G33: IN USH
A34: La Pampa | B34: Allende, Martin Leandro | C34: IN SRO1 | E34: La Pampa | F34: Allende, Martin Leandro | G34: IN SRO1
A35: La Pampa | B35: Heinz, Carlos | C35: IN PCO1 | E35: La Pampa | F35: Heinz, Carlos | G35: IN PCO1
A36: La Pampa | B36: Hernandez, Marcos Alberto | C36: IN PCO | E36: La Pampa | F36: Hernandez, Marcos Alberto | G36: IN PCO
A37: La Pampa | B37: Sanchez, Claudio | C37: IN SRO | E37: La Pampa | F37: Sanchez, Claudio | G37: IN SRO
A38: Oeste | B38: Aldayturriaga, Martin | C38: IN TDL | E38: Oeste | F38: Aldayturriaga, Martin | G38: IN TDL
A39: Oeste | B39: Garcia, Alejandro Javier | C39: IN TRQ | E39: Oeste | F39: Garcia, Alejandro Javier | G39: IN TRQ
A40: Oeste | B40: Martos, Jose Angel | C40: IN OLA | E40: Oeste | F40: Martos, Jose Angel | G40: IN OLA
A41: Sur | B41: Godoy, Diego | C41: IN TRE | E41: Sur | F41: Godoy, Diego | G41: IN TRE
A42: Sur | B42: Gonzalez Cabrera, Antonio | C42: IN COM1 | E42: Sur | F42: Gonzalez Cabrera, Antonio | G42: IN COM1
...

Sheet Control Inicio
A1: Técnico | B1: Zona Local | C1: TECNICO | D1: Estado | E1: Cliente | F1: Luno | G1: Direccion | H1: Localidad | I1: Hora Coordinada | J1: Fecha Vto | L1: =NOW() -> 46086.392
A2: =_xlfn.XLOOKUP(Control_Inicio[[#This Row],[TECNICO]],Tabla8[Nombre Flow], Tabla8[Foto],"",0) -> #VALUE! | B2: Atlántica | C2: Buratti, Fabian | D2: SEG Asistencia | E2: BAPRO | F2: 11369 | G2: Av. Constitucion 5850 | H2: Mar Del Plata | I2: 0.41666667 | J2: Hasta 02/03/2026 13:00:00
A3: =_xlfn.XLOOKUP(Control_Inicio[[#This Row],[TECNICO]],Tabla8[Nombre Flow], Tabla8[Foto],"",0) -> #VALUE! | B3: Atlántica | C3: Castaño, Matias | D3: SEG Registrado | E3: ACA | F3: 002359016370 | G3: Diagonal F De La Palza 1733 | H3: Miramar | I3: 0.47916667 | J3: Hasta 02/03/2026 18:15:52
A4: =_xlfn.XLOOKUP(Control_Inicio[[#This Row],[TECNICO]],Tabla8[Nombre Flow], Tabla8[Foto],"",0) -> #VALUE! | B4: Atlántica | C4: Chiriello, Pablo Javier | D4: SEG Asistencia | E4: BAPRO | F4: 8728 | G4: Av. J. Peralta Ramos 1890 | H4: Mar Del Plata | I4: 0.33333333 | J4: Hasta 02/03/2026 13:00:00
A5: =_xlfn.XLOOKUP(Control_Inicio[[#This Row],[TECNICO]],Tabla8[Nombre Flow], Tabla8[Foto],"",0) -> #VALUE! | B5: Atlántica | C5: Chiriello, Pablo Javier | D5: SEG Control Final | E5: BAPRO | F5: 11347 | G5: Av. Mario Bravo 3650 | H5: Mar Del Plata | I5: 0.4375 | J5: Hasta 27/02/2026 11:22:48
A6: =_xlfn.XLOOKUP(Control_Inicio[[#This Row],[TECNICO]],Tabla8[Nombre Flow], Tabla8[Foto],"",0) -> #VALUE! | B6: Atlántica | C6: Chiriello, Pablo Javier | D6: SEG Asistencia | E6: BAPRO | F6: 11347 | G6: Av. Mario Bravo 3650 | H6: Mar Del Plata | I6: 0.45833333 | J6: Hasta 05/01/2026 16:48:41
A7: =_xlfn.XLOOKUP(Control_Inicio[[#This Row],[TECNICO]],Tabla8[Nombre Flow], Tabla8[Foto],"",0) -> #VALUE! | B7: Atlántica | C7: Chiriello, Pablo Javier | D7: SEG Registrado | E7: BAPRO | F7: 6571 | G7: Calle 64 3000 | H7: Necochea | I7: 0.58333333 | J7: Hasta 03/03/2026 10:05:08
A8: =_xlfn.XLOOKUP(Control_Inicio[[#This Row],[TECNICO]],Tabla8[Nombre Flow], Tabla8[Foto],"",0) -> #VALUE! | B8: Atlántica | C8: Montiel, Juan Fernando | D8: Sin pedidos asignados
A9: =_xlfn.XLOOKUP(Control_Inicio[[#This Row],[TECNICO]],Tabla8[Nombre Flow], Tabla8[Foto],"",0) -> #VALUE! | B9: Centro | C9: Pavon, Diego Emanuel | D9: SEG Asistencia | E9: BANCO CREDICOOP | F9: 812961 | G9: Garibaldi 360 | H9: Bahia Blanca | I9: 0.375 | J9: Hasta 03/03/2026 11:59:37
A10: =_xlfn.XLOOKUP(Control_Inicio[[#This Row],[TECNICO]],Tabla8[Nombre Flow], Tabla8[Foto],"",0) -> #VALUE! | B10: Centro | C10: Pavon, Diego Emanuel | D10: SEG Asistencia | E10: BANCO CREDICOOP | F10: 812931 | G10: Garibaldi 360 | H10: Bahia Blanca | I10: 0.375 | J10: Hasta 03/03/2026 11:57:07
A11: =_xlfn.XLOOKUP(Control_Inicio[[#This Row],[TECNICO]],Tabla8[Nombre Flow], Tabla8[Foto],"",0) -> #VALUE! | B11: Centro | C11: Pavon, Diego Emanuel | D11: SEG Asistencia | E11: BANCO CREDICOOP | F11: 812951 | G11: Garibaldi 360 | H11: Bahia Blanca | I11: 0.375 | J11: Hasta 07/01/2026 14:00:00
A12: =_xlfn.XLOOKUP(Control_Inicio[[#This Row],[TECNICO]],Tabla8[Nombre Flow], Tabla8[Foto],"",0) -> #VALUE! | B12: Centro | C12: Pavon, Diego Emanuel | D12: SEG Asistencia | E12: BANCO CREDICOOP | F12: 812931 | G12: Garibaldi 360 | H12: Bahia Blanca | I12: 0.375 | J12: Hasta 07/01/2026 14:00:00
A13: =_xlfn.XLOOKUP(Control_Inicio[[#This Row],[TECNICO]],Tabla8[Nombre Flow], Tabla8[Foto],"",0) -> #VALUE! | B13: Centro | C13: Pavon, Diego Emanuel | D13: SEG Asistencia | E13: BANCO CREDICOOP | F13: 812951 | G13: Garibaldi 360 | H13: Bahia Blanca | I13: 0.375 | J13: Hasta 03/03/2026 11:57:40
A14: =_xlfn.XLOOKUP(Control_Inicio[[#This Row],[TECNICO]],Tabla8[Nombre Flow], Tabla8[Foto],"",0) -> #VALUE! | B14: Centro | C14: Pavon, Diego Emanuel | D14: SEG Registrado | E14: BANCO CREDICOOP | F14: 812051 | G14: Sarmiento 2200 | H14: Bahia Blanca | I14: 0.54166667 | J14: Hasta 03/03/2026 14:00:00
A15: =_xlfn.XLOOKUP(Control_Inicio[[#This Row],[TECNICO]],Tabla8[Nombre Flow], Tabla8[Foto],"",0) -> #VALUE! | B15: Centro | C15: Rodriguez, Mateo Joaquin | D15: Sin pedidos asignados
A16: =_xlfn.XLOOKUP(Control_Inicio[[#This Row],[TECNICO]],Tabla8[Nombre Flow], Tabla8[Foto],"",0) -> #VALUE! | B16: Centro | C16: Vicente, Francisco Ariel | D16: Sin pedidos asignados
A17: =_xlfn.XLOOKUP(Control_Inicio[[#This Row],[TECNICO]],Tabla8[Nombre Flow], Tabla8[Foto],"",0) -> #VALUE! | B17: Contratistas | C17: Barrera, Fernando Andrés | D17: Sin pedidos asignados
A18: =_xlfn.XLOOKUP(Control_Inicio[[#This Row],[TECNICO]],Tabla8[Nombre Flow], Tabla8[Foto],"",0) -> #VALUE! | B18: Contratistas | C18: Corti Victor | D18: Sin pedidos asignados
A19: =_xlfn.XLOOKUP(Control_Inicio[[#This Row],[TECNICO]],Tabla8[Nombre Flow], Tabla8[Foto],"",0) -> #VALUE! | B19: Contratistas | C19: Foschi, Alejandro | D19: Sin pedidos asignados
A20: =_xlfn.XLOOKUP(Control_Inicio[[#This Row],[TECNICO]],Tabla8[Nombre Flow], Tabla8[Foto],"",0) -> #VALUE! | B20: La Pampa | C20: Allende, Martin Leandro | D20: SEG Control Final | E20: BANCO NACION | F20: 4136 | G20: Avda. General San Martín Oeste 1 | H20: Santa Rosa | I20: 0.33333333 | J20: Hasta 05/01/2026 14:00:00
A21: =_xlfn.XLOOKUP(Control_Inicio[[#This Row],[TECNICO]],Tabla8[Nombre Flow], Tabla8[Foto],"",0) -> #VALUE! | B21: La Pampa | C21: Hernandez, Marcos Alberto | D21: SEG Asistencia | E21: CLIENTE INTERNO | F21: SRO | G21: Fiorucci 45 | H21: Santa Rosa | I21: 0.38888889 | J21: Hasta 02/03/2026 09:18:00
A22: =_xlfn.XLOOKUP(Control_Inicio[[#This Row],[TECNICO]],Tabla8[Nombre Flow], Tabla8[Foto],"",0) -> #VALUE! | B22: Oeste | C22: Aldayturriaga, Martin | D22: SEG Registrado | E22: BAPRO | F22: 11488 | G22: Avellaneda 199 | H22: General Madariaga | I22: 0.58333333 | J22: SLA 02/03/2026 17:55:19
A23: =_xlfn.XLOOKUP(Control_Inicio[[#This Row],[TECNICO]],Tabla8[Nombre Flow], Tabla8[Foto],"",0) -> #VALUE! | B23: Oeste | C23: Aldayturriaga, Martin | D23: SEG Registrado | E23: ARCOS DORADOS | F23: 005091015170 | G23: Av. Bunge 682 | H23: Pinamar | I23: 0.58333333 | J23: Hasta 25/02/2026 18:01:12
A24: =_xlfn.XLOOKUP(Control_Inicio[[#This Row],[TECNICO]],Tabla8[Nombre Flow], Tabla8[Foto],"",0) -> #VALUE! | B24: Oeste | C24: Garcia, Alejandro Javier | D24: SEG Asistencia | E24: BAPRO | F24: 11214 | G24: San Martin 1 | H24: Pellegrini | I24: 0.4375 | J24: Hasta 02/03/2026 13:32:32
A25: =_xlfn.XLOOKUP(Control_Inicio[[#This Row],[TECNICO]],Tabla8[Nombre Flow], Tabla8[Foto],"",0) -> #VALUE! | B25: Oeste | C25: Martos, Jose Angel | D25: SEG Asistencia | E25: BAPRO | F25: 11203 | G25: Los Ligustros S/N | H25: Olavarria | I25: 0.375 | J25: Hasta 06/01/2026 17:00:00
A26: =_xlfn.XLOOKUP(Control_Inicio[[#This Row],[TECNICO]],Tabla8[Nombre Flow], Tabla8[Foto],"",0) -> #VALUE! | B26: Oeste | C26: Martos, Jose Angel | D26: SEG Asistencia | E26: BAPRO | F26: 11202 | G26: Los Ligustros S/N | H26: Olavarria | I26: 0.375 | J26: Hasta 06/01/2026 17:00:00
A27: =_xlfn.XLOOKUP(Control_Inicio[[#This Row],[TECNICO]],Tabla8[Nombre Flow], Tabla8[Foto],"",0) -> #VALUE! | B27: Oeste | C27: Martos, Jose Angel | D27: SEG Registrado | E27: BANCO CREDICOOP | F27: 823031 | G27: Vicente Lopez 3045 | H27: Olavarria | I27: 0.52083333 | J27: Hasta 07/01/2026 14:00:00
A28: =_xlfn.XLOOKUP(Control_Inicio[[#This Row],[TECNICO]],Tabla8[Nombre Flow], Tabla8[Foto],"",0) -> #VALUE! | B28: Oeste | C28: Martos, Jose Angel | D28: SEG Registrado | E28: BANCO CREDICOOP | F28: 823031 | G28: Vicente Lopez 3045 | H28: Olavarria | I28: 0.52083333 | J28: Hasta 04/03/2026 10:10:34
A29: =_xlfn.XLOOKUP(Control_Inicio[[#This Row],[TECNICO]],Tabla8[Nombre Flow], Tabla8[Foto],"",0) -> #VALUE! | B29: Sur | C29: Godoy, Diego | D29: SEG Asistencia | E29: BANCO NACION | F29: 5060 | G29: 9 de Julio 127 | H29: Puerto Madryn | I29: 0.41666667 | J29: Hasta 27/02/2026 14:54:40
A30: =_xlfn.XLOOKUP(Control_Inicio[[#This Row],[TECNICO]],Tabla8[Nombre Flow], Tabla8[Foto],"",0) -> #VALUE! | B30: Sur | C30: Godoy, Diego | D30: SEG Registrado | E30: CENCOSUD S.A | F30: 008681061970 | G30: Manuel Belgrano 372 | H30: Puerto Madryn | I30: 0.5 | J30: Hasta 02/03/2026 16:55:22
A31: =_xlfn.XLOOKUP(Control_Inicio[[#This Row],[TECNICO]],Tabla8[Nombre Flow], Tabla8[Foto],"",0) -> #VALUE! | B31: Sur | C31: Godoy, Diego | D31: SEG Espera Llegada | E31: BANCO CREDICOOP | F31: 814621 | G31: 9 de Julio 270 | H31: Trelew | I31: 0.54166667 | J31: Hasta 02/03/2026 11:34:10
... A34: =_xlfn.XLOOKUP(Control_Inicio[[#This Row],[TECNICO]],Tabla8[Nombre Flow], Tabla8[Foto],"",0) -> #VALUE! | B34: Sur | C34: Gonzalez Cabrera, Antonio | D34: SEG Asistencia | E34: BANCO CREDICOOP | F34: 808251 | G34: Pellegrini 851 | H34: Comodoro Rivadavia | I34: 0.35416667 | J34: Hasta 08/01/2026 08:52:27
A35: =_xlfn.XLOOKUP(Control_Inicio[[#This Row],[TECNICO]],Tabla8[Nombre Flow], Tabla8[Foto],"",0) -> #VALUE! | B35: Suroeste | C35: Ibañez, Pablo Fernando | D35: Sin pedidos asignados
A36: =_xlfn.XLOOKUP(Control_Inicio[[#This Row],[TECNICO]],Tabla8[Nombre Flow], Tabla8[Foto],"",0) -> #VALUE! | B36: Suroeste | C36: Lazzaro, Leonardo | D36: Sin pedidos asignados
A37: =_xlfn.XLOOKUP(Control_Inicio[[#This Row],[TECNICO]],Tabla8[Nombre Flow], Tabla8[Foto],"",0) -> #VALUE! | B37: Suroeste | C37: Meneses, Cristian | D37: Sin pedidos asignados

Sheet Asignados
A1: =Asignados[[#Totals],[Cliente]] -> 37
A2: Pedido | B2: Estado | C2: Cpto Llamada | D2: Cliente | E2: Luno | F2: Direccion | G2: Localidad | H2: LATITUD | I2: LONGITUD | J2: Stock | K2: Despachos | L2: Tec Asignado | M2: F Alta | N2: Marca Coordinación | O2: Fecha Vto | P2: Desc Problema | Q2: Detalle Falla | R2: Modelo | S2: Tec Zona | T2: Zona Local | U2: Provincia | V2: País
A3: 101162952 | B3: SEG Registrado | C3: SERVICE CALL | D3: BAPRO | E3: 11488 | F3: Avellaneda 199 | G3: General Madariaga | H3: -36.541359 | I3: -56.689995 | L3: Aldayturriaga, Martin | M3: 46083 | N3: 2/3/2026 14:00 | O3: SLA 02/03/2026 17:55:19 | P3: ATM-LECTORA DE TARJETA | Q3: falla en la lectora de tarjetas | R3: DT-7000H22V | S3: Montiel, Juan Fernando | T3: Atlántica | U3: Buenos Aires | V3: Argentina
A4: 101161452 | B4: SEG Registrado | C4: SERVICE CALL | D4: ARCOS DORADOS | E4: 005091015170 | F4: Av. Bunge 682 | G4: Pinamar | H4: -37.11108 | I4: -56.86523 | J4: 200182605 | K4: Repuesto Enviado | L4: Aldayturriaga, Martin | M4: 46076 | N4: 2/3/2026 14:00 | O4: Hasta 25/02/2026 18:01:12 | P4: SMC-ASISTENCIA POR FALLA | Q4: Se solicita asistencia para el cliente de referencia ya que tiene error en sensor de bolsa. Equipo con valores 2% | R4: CTE2 SNBC -C | S4: Montiel, Juan Fernando | T4: Atlántica | U4: Buenos Aires | V4: Argentina
A5: 101144122 | B5: SEG Control Final | C5: MTM | D5: BANCO NACION | E5: 4136 | F5: Avda. General San Martín Oeste 1 | G5: Santa Rosa | H5: -36.618133 | I5: -64.299688 | L5: Allende, Martin Leandro | M5: 46025 | N5: 2/3/2026 08:00 | O5: Hasta 05/01/2026 14:00:00 | P5: ATM-Mantenimiento preventivo | Q5: MANTENIMIENTO PREVENTIVO 1er. SEMESTRE 2026. Anexar foto del ATM antes y después de la actividad. | R5: DT-7000H34N (FECT) | S5: Allende, Martin Leandro | T5: La Pampa | U5: La Pampa | V5: Argentina
A6: 101145353 | B6: SEG Registrado | C6: MTM | D6: BANCO NACION | E6: 10298 | F6: Avda. De Los Mineros 550 | G6: Rio Turbio | H6: -51.53911 | I6: -72.338294 | L6: Barrera, Fernando Andrés | M6: 46025 | N6: 13/1/2026 08:00 | O6: Hasta 06/01/2026 13:00:00 | P6: ATM-Mantenimiento preventivo | Q6: MANTENIMIENTO PREVENTIVO 1er. SEMESTRE 2026. Anexar foto del ATM antes y después de la actividad. | R6: ATM OPTEVA 522 | S6: Barrera, Fernando Andrés | T6: Contratistas | U6: Santa Cruz | V6: Argentina
A7: 101144492 | B7: SEG Registrado | C7: MTM | D7: BANCO NACION | E7: 7947 | F7: Calle 15 N° 551 | G7: Balcarce | H7: -37.84638 | I7: -58.25549 | L7: Buratti, Fabian | M7: 46025 | N7: 24/2/2026 12:15 | O7: Hasta 05/01/2026 16:00:00 | P7: ATM-Mantenimiento preventivo | Q7: MANTENIMIENTO PREVENTIVO 1er. SEMESTRE 2026. Anexar foto del ATM antes y después de la actividad. | R7: DT-7000H22V | S7: Buratti, Fabian | T7: Atlántica | U7: Buenos Aires | V7: Argentina
A8: 101145114 | B8: SEG Registrado | C8: MTM | D8: BANCO NACION | E8: 10478 | F8: Gral. San Martín 2594 | G8: Mar Del Plata | H8: -37.999208 | I8: -57.559081 | L8: Buratti, Fabian | M8: 46025 | N8: 27/2/2026 09:00 | O8: Hasta 05/01/2026 15:00:00 | P8: ATM-Mantenimiento preventivo | Q8: MANTENIMIENTO PREVENTIVO 1er. SEMESTRE 2026. Anexar foto del ATM antes y después de la actividad. | R8: ATM OPTEVA 522 | S8: Buratti, Fabian | T8: Atlántica | U8: Buenos Aires | V8: Argentina
A9: 101162470 | B9: SEG Asistencia | C9: SERVICE CALL | D9: BAPRO | E9: 11369 | F9: Av. Constitucion 5850 | G9: Mar Del Plata | H9: -37.999208 | I9: -57.559081 | L9: Buratti, Fabian | M9: 46080 | N9: 2/3/2026 10:00 | O9: Hasta 02/03/2026 13:00:00 | P9: ATM-DEPÓSITO | Q9: - Falla : presenta falla en la zona de recepción del efectivo. El módulo no está operativo._x000D_ _x000D_ se agrega Falla: esta trabado el módulo de dispensador. | R9: DT-7000H34N | S9: Buratti, Fabian | T9: Atlántica | U9: Buenos Aires | V9: Argentina
A10: 101162906 | B10: SEG Registrado | C10: SERVICE CALL | D10: ACA | E10: 002359016370 | F10: Diagonal F De La Palza 1733 | G10: Miramar | H10: -38.26655 | I10: -57.834387 | L10: Castaño, Matias | M10: 46082 | N10: 2/3/2026 11:30 | O10: Hasta 02/03/2026 18:15:52 | P10: SMC-IMPRESORA | Q10: Cliente reporta que no le imprime el dispositivo, se ejecutaron las siguientes pruebas:_x000D_ Simulación de cambio de papel_x000D_ Test Print automático (fallido)_x000D_ Página de prueba de Windows (fallida)_x000D_ Configuración completa en CAOS (correcta)_x000D_ Verificación de coincidencia del nombre_x000D_ Seteo desde modo Supervisor_x000D_ _x000D_ La impresora continúa sin imprimir en ningún escenario._x000D_ Posible falla física del módulo de impresión y no un problema de configuración._x000D_ Se solicita asistencia técnica para su verificación +5492291401747 | R10: CIMA SDM500 | S10: Castaño, Matias | T10: Atlántica | U10: Buenos Aires | V10: Argentina
A11: 101162995 | B11: SEG Registrado | C11: SERVICE CALL | D11: BAPRO | E11: 6571 | F11: Calle 64 3000 | G11: Necochea | H11: -38.359431 | I11: -59.613727 | L11: Chiriello, Pablo Javier | M11: 46083 | N11: 2/3/2026 14:00 | O11: Hasta 03/03/2026 10:05:08 | P11: ATM-IMPRESORA DE RECIBO | Q11: - Falla : presenta falla en la impresión de ticket.Es un error constante que deja el atm fuera de servicio. Por el momento se encuentra funcionando , pero son arreglos temporales. | R11: DT-7000H34N | S11: Chiriello, Pablo Javier | T11: Atlántica | U11: Buenos Aires | V11: Argentina
A12: 101162436 | B12: SEG Asistencia | C12: SERVICE CALL | D12: BAPRO | E12: 8728 | F12: Av. J. Peralta Ramos 1890 | G12: Mar Del Plata | H12: -37.999208 | I12: -57.559081 | J12: 200182779 | K12: Repuesto Pendiente | L12: Chiriello, Pablo Javier | M12: 46080 | N12: 2/3/2026 08:00 | O12: Hasta 02/03/2026 13:00:00 | P12: ATM-LECTORA DE TARJETA | Q12: Falla: falla en lectora de tarjetas, queda en servicio con falla. | R12: DT-7000H22V | S12: Chiriello, Pablo Javier | T12: Atlántica | U12: Buenos Aires | V12: Argentina
A13: 101161660 | B13: SEG Control Final | C13: SERVICE CALL | D13: BAPRO | E13: 11347 | F13: Av. Mario Bravo 3650 | G13: Mar Del Plata | H13: -37.999208 | I13: -57.559081 | J13: 200182716 | K13: Repuesto Enviado | L13: Chiriello, Pablo Javier | M13: 46077 | N13: 2/3/2026 10:30 | O13: Hasta 27/02/2026 11:22:48 | P13: ATM-VERIFICACIÓN DE FALLA | Q13: Falla: Pantalla cliente poco brillo. por favor revisar/ajustar/reemplaza | R13: DT-7000H22V | S13: Chiriello, Pablo Javier | T13: Atlántica | U13: Buenos Aires | V13: Argentina
A14: 101146210 | B14: SEG Asistencia | C14: MTM | D14: BAPRO | E14: 11347 | F14: Av. Mario Bravo 3650 | G14: Mar Del Plata | H14: -37.999208 | I14: -57.559081 | L14: Chiriello, Pablo Javier | M14: 46027 | N14: 2/3/2026 11:00 | O14: Hasta 05/01/2026 16:48:41 | P14: ATM-Mantenimiento preventivo | Q14: Mantenimiento Preventivo Primer Semestre 2026 | R14: DT-7000H22V | S14: Chiriello, Pablo Javier | T14: Atlántica | U14: Buenos Aires | V14: Argentina
A15: 101160721 | B15: SEG Asistencia | C15: AIEC | D15: CLIENTE INTERNO | E15: MDP | F15: Alvear 4862 | G15: Mar Del Plata | H15: -37.999208 | I15: -57.559081 | L15: Deus, Mariano | M15: 46073 | N15: 20/2/2026 10:15 | O15: Hasta 20/02/2026 09:51:58 | P15: GI-TAREAS GENERALES | Q15: Tareas en planta/ generales | R15: ATM | S15: Buratti, Fabian | T15: Atlántica | U15: Buenos Aires | V15: Argentina
A16: 101160324 | B16: SEG Asistencia | C16: TAD | D16: CLIENTE INTERNO | E16: MDP | F16: Alvear 4862 | G16: Mar Del Plata | H16: -37.999208 | I16: -57.559081 | L16: Deus, Mariano | M16: 46071 | N16: 18/2/2026 15:23 | O16: Hasta 18/02/2026 15:20:50 | P16: GI-CONTROL DE STOCK | Q16: Entrega de Repuesto Stock Regional MDP | R16: ATM | S16: Buratti, Fabian | T16: Atlántica | U16: Buenos Aires | V16: Argentina
A17: 101161411 | B17: SEG Asistencia | C17: TAD | D17: BAPRO | E17: 11090 | F17: General Paz 299 | G17: Coronel Vidal | H17: -37.44652 | I17: -57.72939 | L17: Deus, Mariano | M17: 46076 | N17: 24/2/2026 09:00 | O17: Hasta 24/02/2026 13:00:00 | P17: ATM-AUDITORIA | Q17: Auditoría ATM | R17: DT-7000H34N | S17: Buratti, Fabian | T17: Atlántica | U17: Buenos Aires | V17: Argentina
A18: 101162414 | B18: SEG Asistencia | C18: SERVICE CALL | D18: BAPRO | E18: 11214 | F18: San Martin 1 | G18: Pellegrini | H18: -36.26785 | I18: -63.164671 | J18: 200182749 | K18: Repuesto Enviado | L18: Garcia, Alejandro Javier | M18: 46080 | N18: 2/3/2026 10:30 | O18: Hasta 02/03/2026 13:32:32 | P18: ATM-DISPENSADOR | Q18: traba billetes | R18: DT-7000H34N | S18: Garcia, Alejandro Javier | T18: Oeste | U18: Buenos Aires | V18: Argentina
A19: 101144432 | B19: SEG Registrado | C19: MTM | D19: BANCO NACION | E19: 4203 | F19: Rivadavia 698 | G19: General Villegas | H19: -35.3261 | I19: -63.1477 | L19: Garcia, Alejandro Javier | M19: 46025 | N19: 27/2/2026 12:30 | O19: Hasta 06/01/2026 09:00:00 | P19: ATM-Mantenimiento preventivo | Q19: MANTENIMIENTO PREVENTIVO 1er. SEMESTRE 2026. Anexar foto del ATM antes y después de la actividad. | R19: DT-7000H34N (FECT) | S19: Garcia, Alejandro Javier | T19: Oeste | U19: Buenos Aires | V19: Argentina
